Workbook
Name UPDATE: 'Data Sheet'!$E$1

Sheet Profit & Loss
A1: ='Data Sheet'!B1 -> TITAN COMPANY LTD | H1: =UPDATE | M1: SCREENER.IN
A3: Narration | B3: ='Data Sheet'!B16 -> 42460 | C3: ='Data Sheet'!C16 -> 42825 | D3: ='Data Sheet'!D16 -> 43190 | E3: ='Data Sheet'!E16 -> 43555 | F3: ='Data Sheet'!F16 -> 43921 | G3: ='Data Sheet'!G16 -> 44286 | H3: ='Data Sheet'!H16 -> 44651 | I3: ='Data Sheet'!I16 -> 45016 | ... K3: ='Data Sheet'!K16 -> 45747 | L3: Trailing | M3: Best Case | N3: Worst Case
A4: Sales | B4: ='Data Sheet'!B17 -> 11275.89 | C4: ='Data Sheet'!C17 -> 13260.83 | D4: ='Data Sheet'!D17 -> 16119.77 | E4: ='Data Sheet'!E17 -> 19778.52 | F4: ='Data Sheet'!F17 -> 21052 | G4: ='Data Sheet'!G17 -> 21644 | H4: ='Data Sheet'!H17 -> 28799 | I4: ='Data Sheet'!I17 -> 40575 | ... K4: ='Data Sheet'!K17 -> 60456 | L4: =SUM(Quarters!H4:K4) -> 75580 | M4: =$K4+M23*K4 -> 77409.348 | N4: =$K4+N23*L4 -> 75959.341
A5: Expenses | B5: =SUM('Data Sheet'!B18,'Data Sheet'!B20:B24, -1*'Data Sheet'!B19) -> 10336.56 | C5: =SUM('Data Sheet'!C18,'Data Sheet'!C20:C24, -1*'Data Sheet'!C19) -> 12096.93 | D5: =SUM('Data Sheet'!D18,'Data Sheet'!D20:D24, -1*'Data Sheet'!D19) -> 14475.57 | E5: =SUM('Data Sheet'!E18,'Data Sheet'!E20:E24, -1*'Data Sheet'!E19) -> 17784.73 | F5: =SUM('Data Sheet'!F18,'Data Sheet'!F20:F24, -1*'Data Sheet'!F19) -> 18589 | G5: =SUM('Data Sheet'!G18,'Data Sheet'!G20:G24, -1*'Data Sheet'!G19) -> 19919 | H5: =SUM('Data Sheet'!H18,'Data Sheet'!H20:H24, -1*'Data Sheet'!H19) -> 25455 | I5: =SUM('Data Sheet'!I18,'Data Sheet'!I20:I24, -1*'Data Sheet'!I19) -> 35693 | ... K5: =SUM('Data Sheet'!K18,'Data Sheet'!K20:K24, -1*'Data Sheet'!K19) -> 54762 | L5: =SUM(Quarters!H5:K5) -> 67625 | M5: =M4-M6 -> 69261.804 | N5: =N4-N6 -> 68166.393
A6: Operating Profit | B6: =B4-B5 -> 939.33 | C6: =C4-C5 -> 1163.9 | D6: =D4-D5 -> 1644.2 | E6: =E4-E5 -> 1993.79 | F6: =F4-F5 -> 2463 | G6: =G4-G5 -> 1725 | H6: =H4-H5 -> 3344 | I6: =I4-I5 -> 4882 | ... K6: =K4-K5 -> 5694 | L6: =SUM(Quarters!H6:K6) -> 7955 | M6: =M4*M24 -> 8147.5438 | N6: =N4*N24 -> 7792.9475
A7: Other Income | B7: ='Data Sheet'!B25 -> 69.33 | C7: ='Data Sheet'!C25 -> -42.38 | D7: ='Data Sheet'!D25 -> 69.93 | E7: ='Data Sheet'!E25 -> 178.48 | F7: ='Data Sheet'!F25 -> 153 | G7: ='Data Sheet'!G25 -> 180 | H7: ='Data Sheet'!H25 -> 177 | I7: ='Data Sheet'!I25 -> 306 | ... K7: ='Data Sheet'!K25 -> 487 | L7: =SUM(Quarters!H7:K7) -> 333 | M7: 0 | N7: 0
A8: Depreciation | B8: ='Data Sheet'!B26 -> 98.19 | C8: ='Data Sheet'!C26 -> 110.53 | D8: ='Data Sheet'!D26 -> 131.43 | E8: ='Data Sheet'!E26 -> 162.84 | F8: ='Data Sheet'!F26 -> 348 | G8: ='Data Sheet'!G26 -> 375 | H8: ='Data Sheet'!H26 -> 399 | I8: ='Data Sheet'!I26 -> 441 | ... K8: ='Data Sheet'!K26 -> 693 | L8: =SUM(Quarters!H8:K8) -> 763 | M8: =+$L8 -> 763 | N8: =+$L8 -> 763
A9: Interest | B9: ='Data Sheet'!B27 -> 42.36 | C9: ='Data Sheet'!C27 -> 37.74 | D9: ='Data Sheet'!D27 -> 52.92 | E9: ='Data Sheet'!E27 -> 52.54 | F9: ='Data Sheet'!F27 -> 166 | G9: ='Data Sheet'!G27 -> 203 | H9: ='Data Sheet'!H27 -> 218 | I9: ='Data Sheet'!I27 -> 300 | ... K9: ='Data Sheet'!K27 -> 953 | L9: =SUM(Quarters!H9:K9) -> 1082 | M9: =+$L9 -> 1082 | N9: =+$L9 -> 1082
A10: Profit before tax | B10: ='Data Sheet'!B28 -> 868.11 | C10: ='Data Sheet'!C28 -> 973.25 | D10: ='Data Sheet'!D28 -> 1529.78 | E10: ='Data Sheet'!E28 -> 1956.89 | F10: ='Data Sheet'!F28 -> 2102 | G10: ='Data Sheet'!G28 -> 1327 | H10: ='Data Sheet'!H28 -> 2904 | I10: ='Data Sheet'!I28 -> 4447 | ... K10: ='Data Sheet'!K28 -> 4535 | L10: =SUM(Quarters!H10:K10) -> 6443 | M10: =M6+M7-SUM(M8:M9) -> 6302.5438 | N10: =N6+N7-SUM(N8:N9) -> 5947.9475
A11: Tax | B11: ='Data Sheet'!B29 -> 191.59 | C11: ='Data Sheet'!C29 -> 275.97 | D11: ='Data Sheet'!D29 -> 427.87 | E11: ='Data Sheet'!E29 -> 568.24 | F11: ='Data Sheet'!F29 -> 609 | G11: ='Data Sheet'!G29 -> 353 | H11: ='Data Sheet'!H29 -> 706 | I11: ='Data Sheet'!I29 -> 1173 | ... K11: ='Data Sheet'!K29 -> 1198 | L11: =SUM(Quarters!H11:K11) -> 1677 | M11: =IF($L10>0,$L11/$L10,0) -> 0.26028248 | N11: =IF($L10>0,$L11/$L10,0) -> 0.26028248
A12: Net profit | B12: ='Data Sheet'!B30 -> 674.52 | C12: ='Data Sheet'!C30 -> 711.47 | D12: ='Data Sheet'!D30 -> 1130.09 | E12: ='Data Sheet'!E30 -> 1404.15 | F12: ='Data Sheet'!F30 -> 1501 | G12: ='Data Sheet'!G30 -> 973 | H12: ='Data Sheet'!H30 -> 2173 | I12: ='Data Sheet'!I30 -> 3250 | ... K12: ='Data Sheet'!K30 -> 3337 | L12: =SUM(Quarters!H12:K12) -> 4766 | M12: =M10-M11*M10 -> 4662.1021 | N12: =N10-N11*N10 -> 4399.801
A13: EPS | B13: =IF('Data Sheet'!B93>0,B12/'Data Sheet'!B93,0) -> 7.5976571 | C13: =IF('Data Sheet'!C93>0,C12/'Data Sheet'!C93,0) -> 8.0138545 | D13: =IF('Data Sheet'!D93>0,D12/'Data Sheet'!D93,0) -> 12.729106 | E13: =IF('Data Sheet'!E93>0,E12/'Data Sheet'!E93,0) -> 15.816062 | F13: =IF('Data Sheet'!F93>0,F12/'Data Sheet'!F93,0) -> 16.906961 | G13: =IF('Data Sheet'!G93>0,G12/'Data Sheet'!G93,0) -> 10.959676 | H13: =IF('Data Sheet'!H93>0,H12/'Data Sheet'!H93,0) -> 24.476233 | I13: =IF('Data Sheet'!I93>0,I12/'Data Sheet'!I93,0) -> 36.607344 | ... K13: =IF('Data Sheet'!K93>0,K12/'Data Sheet'!K93,0) -> 37.587294 | L13: =IF('Data Sheet'!$B6>0,'Profit & Loss'!L12/'Data Sheet'!$B6,0) -> 53.691305 | M13: =IF('Data Sheet'!$B6>0,'Profit & Loss'!M12/'Data Sheet'!$B6,0) -> 52.520845 | N13: =IF('Data Sheet'!$B6>0,'Profit & Loss'!N12/'Data Sheet'!$B6,0) -> 49.565895
A14: Price to earning | B14: =IF(B15>0,B15/B13,"") -> 44.592694 | C14: =IF(C15>0,C15/C13,"") -> 57.743749 | D14: =IF(D15>0,D15/D13,"") -> 74.027196 | E14: =IF(E15>0,E15/E13,"") -> 72.195594 | F14: =IF(F15>0,F15/F13,"") -> 55.225773 | G14: =IF(G15>0,G15/G13,"") -> 142.16205 | H14: =IF(H15>0,H15/H13,"") -> 103.61684 | I14: =IF(I15>0,I15/I13,"") -> 68.69933 | ... K14: =IF(K15>0,K15/K13,"") -> 81.499614 | L14: =IF(L13>0,L15/L13,0) -> 79.083569 | M14: =M25 -> 81.457056 | N14: =N25 -> 79.083569
A15: Price | B15: ='Data Sheet'!B90 -> 338.8 | C15: ='Data Sheet'!C90 -> 462.75 | D15: ='Data Sheet'!D90 -> 942.3 | E15: ='Data Sheet'!E90 -> 1141.85 | F15: ='Data Sheet'!F90 -> 933.7 | G15: ='Data Sheet'!G90 -> 1558.05 | H15: ='Data Sheet'!H90 -> 2536.15 | I15: ='Data Sheet'!I90 -> 2514.9 | ... K15: ='Data Sheet'!K90 -> 3063.35 | L15: ='Data Sheet'!B8 -> 4246.1 | M15: =M13*M14 -> 4278.1934 | N15: =N13*N14 -> 3919.8479
A17: RATIOS:
A18: Dividend Payout | B18: =IF('Data Sheet'!B30>0, 'Data Sheet'!B31/'Data Sheet'!B30, 0) -> 0.28956888 | C18: =IF('Data Sheet'!C30>0, 'Data Sheet'!C31/'Data Sheet'!C30, 0) -> 0.32444095 | D18: =IF('Data Sheet'!D30>0, 'Data Sheet'!D31/'Data Sheet'!D30, 0) -> 0.29459601 | E18: =IF('Data Sheet'!E30>0, 'Data Sheet'!E31/'Data Sheet'!E30, 0) -> 0.31613432 | F18: =IF('Data Sheet'!F30>0, 'Data Sheet'!F31/'Data Sheet'!F30, 0) -> 0.23717522 | G18: =IF('Data Sheet'!G30>0, 'Data Sheet'!G31/'Data Sheet'!G30, 0) -> 0.36587873 | H18: =IF('Data Sheet'!H30>0, 'Data Sheet'!H31/'Data Sheet'!H30, 0) -> 0.30717902 | I18: =IF('Data Sheet'!I30>0, 'Data Sheet'!I31/'Data Sheet'!I30, 0) -> 0.27384615 | ... K18: =IF('Data Sheet'!K30>0, 'Data Sheet'!K31/'Data Sheet'!K30, 0) -> 0.29337728
A19: OPM | B19: =IF(B6>0,B6/B4,0) -> 0.083304289 | C19: =IF(C6>0,C6/C4,0) -> 0.08776977 | D19: =IF(D6>0,D6/D4,0) -> 0.10199897 | E19: =IF(E6>0,E6/E4,0) -> 0.10080582 | F19: =IF(F6>0,F6/F4,0) -> 0.11699601 | G19: =IF(G6>0,G6/G4,0) -> 0.079698762 | H19: =IF(H6>0,H6/H4,0) -> 0.11611514 | I19: =IF(I6>0,I6/I4,0) -> 0.12032039 | ... L19: =IF(L6>0,L6/L4,0) -> 0.10525271
G22: TRENDS: | H22: 10 YEARS | I22: 7 YEARS | J22: 5 YEARS | K22: 3 YEARS | L22: RECENT | M22: BEST | N22: WORST
G23: Sales Growth | H23: =IF(B4=0,"",POWER($K4/B4,1/9)-1) -> 0.20512491 | I23: =IF(D4=0,"",POWER($K4/D4,1/7)-1) -> 0.20784585 | J23: =IF(F4=0,"",POWER($K4/F4,1/5)-1) -> 0.23489266 | K23: =IF(H4=0,"",POWER($K4/H4, 1/3)-1) -> 0.28042457 | L23: =IF(ISERROR(MAX(IF(J4=0,"",(K4-J4)/J4),IF(K4=0,"",(L4-K4)/K4))),"",MAX(IF(J4=0,"",(K4-J4)/J4),IF(K4=0,"",(L4-K4)/K4))) -> 0.25016541 | M23: =MAX(K23:L23) -> 0.28042457 | N23: =MIN(H23:L23) -> 0.20512491
G24: OPM | H24: =IF(SUM(B4:$K$4)=0,"",SUMPRODUCT(B19:$K$19,B4:$K$4)/SUM(B4:$K$4)) -> 0.10259367 | I24: =IF(SUM(E4:$K$4)=0,"",SUMPRODUCT(E19:$K$19,E4:$K$4)/SUM(E4:$K$4)) -> 0.10433438 | J24: =IF(SUM(G4:$K$4)=0,"",SUMPRODUCT(G19:$K$19,G4:$K$4)/SUM(G4:$K$4)) -> 0.10336299 | K24: =IF(SUM(I4:$K$4)=0, "", SUMPRODUCT(I19:$K$19,I4:$K$4)/SUM(I4:$K$4)) -> 0.10431581 | L24: =L19 -> 0.10525271 | M24: =MAX(K24:L24) -> 0.10525271 | N24: =MIN(H24:L24) -> 0.10259367
G25: Price to Earning | H25: =IF(ISERROR(AVERAGEIF(B14:$L14,">0")),"",AVERAGEIF(B14:$L14,">0")) -> 79.581102 | I25: =IF(ISERROR(AVERAGEIF(E14:$L14,">0")),"",AVERAGEIF(E14:$L14,">0")) -> 87.378561 | J25: =IF(ISERROR(AVERAGEIF(G14:$L14,">0")),"",AVERAGEIF(G14:$L14,">0")) -> 95.267853 | K25: =IF(ISERROR(AVERAGEIF(I14:$L14,">0")),"",AVERAGEIF(I14:$L14,">0")) -> 81.457056 | L25: =L14 -> 79.083569 | M25: =MAX(K25:L25) -> 81.457056 | N25: =MIN(H25:L25) -> 79.083569

Sheet Quarters
A1: ='Profit & Loss'!A1 -> TITAN COMPANY LTD | E1: =UPDATE | J1: SCREENER.IN
A3: Narration | B3: ='Data Sheet'!B41 -> 45199 | C3: ='Data Sheet'!C41 -> 45291 | D3: ='Data Sheet'!D41 -> 45382 | E3: ='Data Sheet'!E41 -> 45473 | F3: ='Data Sheet'!F41 -> 45565 | G3: ='Data Sheet'!G41 -> 45657 | H3: ='Data Sheet'!H41 -> 45747 | I3: ='Data Sheet'!I41 -> 45838 | ... K3: ='Data Sheet'!K41 -> 46022
A4: Sales | B4: ='Data Sheet'!B42 -> 12529 | C4: ='Data Sheet'!C42 -> 14164 | D4: ='Data Sheet'!D42 -> 12494 | E4: ='Data Sheet'!E42 -> 13266 | F4: ='Data Sheet'!F42 -> 14534 | G4: ='Data Sheet'!G42 -> 17740 | H4: ='Data Sheet'!H42 -> 14916 | I4: ='Data Sheet'!I42 -> 16523 | ... K4: ='Data Sheet'!K42 -> 25416
A5: Expenses | B5: ='Data Sheet'!B43 -> 11118 | C5: ='Data Sheet'!C43 -> 12599 | D5: ='Data Sheet'!D43 -> 11303 | E5: ='Data Sheet'!E43 -> 12019 | F5: ='Data Sheet'!F43 -> 13298 | G5: ='Data Sheet'!G43 -> 16066 | H5: ='Data Sheet'!H43 -> 13379 | I5: ='Data Sheet'!I43 -> 14693 | ... K5: ='Data Sheet'!K43 -> 22703
A6: Operating Profit | B6: ='Data Sheet'!B50 -> 1411 | C6: ='Data Sheet'!C50 -> 1565 | D6: ='Data Sheet'!D50 -> 1191 | E6: ='Data Sheet'!E50 -> 1247 | F6: ='Data Sheet'!F50 -> 1236 | G6: ='Data Sheet'!G50 -> 1674 | H6: ='Data Sheet'!H50 -> 1537 | I6: ='Data Sheet'!I50 -> 1830 | ... K6: ='Data Sheet'!K50 -> 2713
A7: Other Income | B7: ='Data Sheet'!B44 -> 125 | C7: ='Data Sheet'!C44 -> 136 | D7: ='Data Sheet'!D44 -> 159 | E7: ='Data Sheet'!E44 -> 120 | F7: ='Data Sheet'!F44 -> 123 | G7: ='Data Sheet'!G44 -> 128 | H7: ='Data Sheet'!H44 -> 116 | I7: ='Data Sheet'!I44 -> 105 | ... K7: ='Data Sheet'!K44 -> -1
A8: Depreciation | B8: ='Data Sheet'!B45 -> 144 | C8: ='Data Sheet'!C45 -> 154 | D8: ='Data Sheet'!D45 -> 158 | E8: ='Data Sheet'!E45 -> 164 | F8: ='Data Sheet'!F45 -> 171 | G8: ='Data Sheet'!G45 -> 175 | H8: ='Data Sheet'!H45 -> 183 | I8: ='Data Sheet'!I45 -> 184 | ... K8: ='Data Sheet'!K45 -> 207
A9: Interest | B9: ='Data Sheet'!B46 -> 140 | C9: ='Data Sheet'!C46 -> 169 | D9: ='Data Sheet'!D46 -> 201 | E9: ='Data Sheet'!E46 -> 230 | F9: ='Data Sheet'!F46 -> 240 | G9: ='Data Sheet'!G46 -> 231 | H9: ='Data Sheet'!H46 -> 252 | I9: ='Data Sheet'!I46 -> 271 | ... K9: ='Data Sheet'!K46 -> 282
A10: Profit before tax | B10: ='Data Sheet'!B47 -> 1252 | C10: ='Data Sheet'!C47 -> 1378 | D10: ='Data Sheet'!D47 -> 991 | E10: ='Data Sheet'!E47 -> 973 | F10: ='Data Sheet'!F47 -> 948 | G10: ='Data Sheet'!G47 -> 1396 | H10: ='Data Sheet'!H47 -> 1218 | I10: ='Data Sheet'!I47 -> 1480 | ... K10: ='Data Sheet'!K47 -> 2223
A11: Tax | B11: ='Data Sheet'!B48 -> 336 | C11: ='Data Sheet'!C48 -> 325 | D11: ='Data Sheet'!D48 -> 220 | E11: ='Data Sheet'!E48 -> 258 | F11: ='Data Sheet'!F48 -> 244 | G11: ='Data Sheet'!G48 -> 349 | H11: ='Data Sheet'!H48 -> 347 | I11: ='Data Sheet'!I48 -> 389 | ... K11: ='Data Sheet'!K48 -> 539
A12: Net profit | B12: ='Data Sheet'!B49 -> 915 | C12: ='Data Sheet'!C49 -> 1053 | D12: ='Data Sheet'!D49 -> 771 | E12: ='Data Sheet'!E49 -> 715 | F12: ='Data Sheet'!F49 -> 704 | G12: ='Data Sheet'!G49 -> 1047 | H12: ='Data Sheet'!H49 -> 871 | I12: ='Data Sheet'!I49 -> 1091 | ... K12: ='Data Sheet'!K49 -> 1684
A14: OPM | B14: =IF(B4>0,B6/B4,"") -> 0.11261872 | C14: =IF(C4>0,C6/C4,"") -> 0.11049139 | D14: =IF(D4>0,D6/D4,"") -> 0.095325756 | E14: =IF(E4>0,E6/E4,"") -> 0.093999698 | F14: =IF(F4>0,F6/F4,"") -> 0.085041971 | G14: =IF(G4>0,G6/G4,"") -> 0.094363021 | H14: =IF(H4>0,H6/H4,"") -> 0.10304371 | I14: =IF(I4>0,I6/I4,"") -> 0.11075471 | ... K14: =IF(K4>0,K6/K4,"") -> 0.10674378

Sheet Titan Beta Regression
B2: Regression Beta - 5 Years Monthly
B4: Titan Company Monthly Returns | F4: NIFTY Returns | I4: Beta Drifting
L5: Beta 1 | M5: =SLOPE(D8:D67,G8:G67) -> 1.1953036
B6: Date | C6: Closing Price | D6: Return | F6: Closing Price | G6: Return | I6: Levered Raw Beta | J6: =M7 -> 1.1953036 | L6: Beta 2 | M6: =_xlfn.COVARIANCE.S(D7:D67,G7:G67)/_xlfn.VAR.S(G7:G67) -> 1.1953036
B7: 44317 | C7: 1571.8 | F7: 15582.8 | I7: Raw Beta Weight | J7: 0.75 | L7: Beta 3 | M7: =M30 -> 1.1953036
B8: 44348 | C8: 1705.97 | D8: =C8/C7-1 -> 0.085360733 | F8: 15721.5 | G8: =F8/F7-1 -> 0.0089008394
B9: 44378 | C9: 1688.29 | D9: =C9/C8-1 -> -0.010363605 | F9: 15763.05 | G9: =F9/F8-1 -> 0.0026428776 | I9: Market Beta | J9: 1
B10: 44409 | C10: 1896.71 | D10: =C10/C9-1 -> 0.12345036 | F10: 17132.2 | G10: =F10/F9-1 -> 0.086858191 | I10: Market Beta Weight | J10: 0.25
B11: 44440 | C11: 2133.85 | D11: =C11/C10-1 -> 0.12502702 | F11: 17618.15 | G11: =F11/F10-1 -> 0.028364717
B12: 44470 | C12: 2352.68 | D12: =C12/C11-1 -> 0.10255173 | F12: 17671.65 | G12: =F12/F11-1 -> 0.0030366412 | I12: Adjusted Beta | J12: =(J6*J7)+(J9*J10) -> 1.1464777
B13: 44501 | C13: 2344.73 | D13: =C13/C12-1 -> -0.0033791251 | F13: 16983.2 | G13: =F13/F12-1 -> -0.038957879 | L13: SUMMARY OUTPUT
B14: 44531 | C14: 2489.73 | D14: =C14/C13-1 -> 0.061840809 | F14: 17354.05 | G14: =F14/F13-1 -> 0.021836285
B15: 44562 | C15: 2329.73 | D15: =C15/C14-1 -> -0.064263996 | F15: 17339.85 | G15: =F15/F14-1 -> -0.0008182528 | L15: Regression Statistics
B16: 44593 | C16: 2513.56 | D16: =C16/C15-1 -> 0.078906139 | F16: 16793.9 | G16: =F16/F15-1 -> -0.031485278 | L16: Multiple R | M16: 0.63417475
B17: 44621 | C17: 2503.3 | D17: =C17/C16-1 -> -0.00408186 | F17: 17464.75 | G17: =F17/F16-1 -> 0.039946052 | L17: R Square | M17: 0.40217762
B18: 44652 | C18: 2426.36 | D18: =C18/C17-1 -> -0.030735429 | F18: 17102.55 | G18: =F18/F17-1 -> -0.020738917 | L18: Adjusted R Square | M18: 0.39187034
B19: 44682 | C19: 2187.3 | D19: =C19/C18-1 -> -0.098526187 | F19: 16584.55 | G19: =F19/F18-1 -> -0.030287881 | L19: Standard Error | M19: 0.055886874
B20: 44713 | C20: 1916.1 | D20: =C20/C19-1 -> -0.12398848 | F20: 15780.25 | G20: =F20/F19-1 -> -0.048496944 | L20: Observations | M20: 60
B21: 44743 | C21: 2321.58 | D21: =C21/C20-1 -> 0.21161735 | F21: 17158.25 | G21: =F21/F20-1 -> 0.087324345
B22: 44774 | C22: 2580.01 | D22: =C22/C21-1 -> 0.11131643 | F22: 17759.3 | G22: =F22/F21-1 -> 0.035029796 | L22: ANOVA
B23: 44805 | C23: 2582.28 | D23: =C23/C22-1 -> 0.00087984155 | F23: 17094.35 | G23: =F23/F22-1 -> -0.037442354 | M23: df | N23: SS | O23: MS | P23: F | Q23: Significance F
B24: 44835 | C24: 2735.37 | D24: =C24/C23-1 -> 0.059284818 | F24: 18012.2 | G24: =F24/F23-1 -> 0.053693179 | L24: Regression | M24: 1 | N24: 0.12186903 | O24: 0.12186903 | P24: 39.018783 | Q24: 5.3279023e-08
B25: 44866 | C25: 2627.9 | D25: =C25/C24-1 -> -0.039289018 | F25: 18758.35 | G25: =F25/F24-1 -> 0.041424701 | L25: Residual | M25: 58 | N25: 0.18115388 | O25: 0.0031233427
B26: 44896 | C26: 2572.92 | D26: =C26/C25-1 -> -0.020921648 | F26: 18105.3 | G26: =F26/F25-1 -> -0.03481383 | L26: Total | M26: 59 | N26: 0.30302291
B27: 44927 | C27: 2354.66 | D27: =C27/C26-1 -> -0.084829688 | F27: 17662.15 | G27: =F27/F26-1 -> -0.024476258
B28: 44958 | C28: 2350.35 | D28: =C28/C27-1 -> -0.0018304129 | F28: 17303.95 | G28: =F28/F27-1 -> -0.020280657 | M28: Coefficients | N28: Standard Error | O28: t Stat | P28: P-value | Q28: Lower 95% | R28: Upper 95% | S28: Lower 95.0% | T28: Upper 95.0%
B29: 44986 | C29: 2491.11 | D29: =C29/C28-1 -> 0.059888953 | F29: 17359.75 | G29: =F29/F28-1 -> 0.0032246973 | L29: Intercept | M29: 0.01061252 | N29: 0.007345298 | O29: 1.4448046 | P29: 0.15389393 | Q29: -0.0040906912 | R29: 0.025315732 | S29: -0.0040906912 | T29: 0.025315732
B30: 45017 | C30: 2616.85 | D30: =C30/C29-1 -> 0.050475491 | F30: 18065 | G30: =F30/F29-1 -> 0.040625585 | L30: X Variable 1 | M30: 1.1953036 | N30: 0.19135568 | O30: 6.2465017 | P30: 5.3279023e-08 | Q30: 0.81226356 | R30: 1.5783436 | S30: 0.81226356 | T30: 1.5783436
B31: 45047 | C31: 2796.54 | D31: =C31/C30-1 -> 0.068666527 | F31: 18534.4 | G31: =F31/F30-1 -> 0.025983947
B32: 45078 | C32: 3018.81 | D32: =C32/C31-1 -> 0.079480358 | F32: 19189.05 | G32: =F32/F31-1 -> 0.035320809
B33: 45108 | C33: 2975.63 | D33: =C33/C32-1 -> -0.014303649 | F33: 19753.8 | G33: =F33/F32-1 -> 0.029430847
B34: 45139 | C34: 3085.04 | D34: =C34/C33-1 -> 0.036768684 | F34: 19253.8 | G34: =F34/F33-1 -> -0.025311586
B35: 45170 | C35: 3129.11 | D35: =C35/C34-1 -> 0.014285066 | F35: 19638.3 | G35: =F35/F34-1 -> 0.019970084
B36: 45200 | C36: 3169.71 | D36: =C36/C35-1 -> 0.012974935 | F36: 19079.6 | G36: =F36/F35-1 -> -0.028449509
B37: 45231 | C37: 3468.78 | D37: =C37/C36-1 -> 0.09435248 | F37: 20133.15 | G37: =F37/F36-1 -> 0.055218663
B38: 45261 | C38: 3652.47 | D38: =C38/C37-1 -> 0.052955218 | F38: 21731.4 | G38: =F38/F37-1 -> 0.079384001
B39: 45292 | C39: 3674.43 | D39: =C39/C38-1 -> 0.0060123697 | F39: 21725.7 | G39: =F39/F38-1 -> -0.00026229327
B40: 45323 | C40: 3601.74 | D40: =C40/C39-1 -> -0.01978266 | F40: 21982.8 | G40: =F40/F39-1 -> 0.011833911
B41: 45352 | C41: 3778.03 | D41: =C41/C40-1 -> 0.048945787 | F41: 22326.9 | G41: =F41/F40-1 -> 0.015653147
B42: 45383 | C42: 3566.81 | D42: =C42/C41-1 -> -0.055907444 | F42: 22604.85 | G42: =F42/F41-1 -> 0.012449108
...

Sheet Bluestone Jewel Regression
B2: Regression Beta - 5 Monthly
B4: Bluestone Jewel Monthly Returns | F4: NIFTY Returns | I4: Beta Drifting
L5: Beta 1 | M5: =SLOPE(D8:D67,G8:G67) -> -1.7078554
B6: Date | C6: Closing Price | D6: Return | F6: Closing Price | G6: Return | I6: Levered Raw Beta | J6: =M7 -> -1.7078554 | L6: Beta 2 | M6: =_xlfn.COVARIANCE.S(D7:D67,G7:G67)/_xlfn.VAR.S(G7:G67) -> -1.7078554 | R6: Date | S6: Adj Close
B7: 45870 | C7: 534.8 | F7: 15582.8 | I7: Raw Beta Weight | J7: 0.75 | L7: Beta 3 | M7: =M29 -> -1.7078554
B8: 45901 | C8: 599.65 | D8: =C8/C7-1 -> 0.12126028 | F8: 15721.5 | G8: =F8/F7-1 -> 0.0089008394
B9: 45931 | C9: 708 | D9: =C9/C8-1 -> 0.18068874 | F9: 15763.05 | G9: =F9/F8-1 -> 0.0026428776 | I9: Market Beta | J9: 1
B10: 45962 | C10: 558.1 | D10: =C10/C9-1 -> -0.21172316 | F10: 17132.2 | G10: =F10/F9-1 -> 0.086858191 | I10: Market Beta Weight | J10: 0.25
B11: 45992 | C11: 470.75 | D11: =C11/C10-1 -> -0.15651317 | F11: 17618.15 | G11: =F11/F10-1 -> 0.028364717
B12: 46023 | C12: 440.1 | D12: =C12/C11-1 -> -0.065108869 | F12: 17671.65 | G12: =F12/F11-1 -> 0.0030366412 | I12: Adjusted Beta | J12: =(J6*J7)+(J9*J10) -> -1.0308916 | L12: SUMMARY OUTPUT
B13: 46054 | C13: 437.45 | D13: =C13/C12-1 -> -0.0060213588 | F13: 16983.2 | G13: =F13/F12-1 -> -0.038957879
B14: 46082 | C14: 467.15 | D14: =C14/C13-1 -> 0.067893474 | F14: 17354.05 | G14: =F14/F13-1 -> 0.021836285 | L14: Regression Statistics
B15: 46113 | C15: 427.55 | D15: =C15/C14-1 -> -0.084769346 | F15: 17339.85 | G15: =F15/F14-1 -> -0.0008182528 | L15: Multiple R | M15: 0.49009433
B16: 46118 | C16: 427.45 | D16: =C16/C15-1 -> -0.00023389077 | F16: 16793.9 | G16: =F16/F15-1 -> -0.031485278 | L16: R Square | M16: 0.24019245
L17: Adjusted R Square | M17: 0.13164852
L18: Standard Error | M18: 0.11883109
L19: Observations | M19: 9
L21: ANOVA
M22: df | N22: SS | O22: MS | P22: F | Q22: Significance F
L23: Regression | M23: 1 | N23: 0.031247405 | O23: 0.031247405 | P23: 2.2128593 | Q23: 0.18046324
L24: Residual | M24: 7 | N24: 0.098845795 | O24: 0.014120828
L25: Total | M25: 8 | N25: 0.1300932
M27: Coefficients | N27: Standard Error | O27: t Stat | P27: P-value | Q27: Lower 95% | R27: Upper 95% | S27: Lower 95.0% | T27: Upper 95.0%
L28: Intercept | M28: -0.0019170067 | N28: 0.040915937 | O28: -0.046852322 | P28: 0.96393959 | Q28: -0.098667825 | R28: 0.094833811 | S28: -0.098667825 | T28: 0.094833811
L29: X Variable 1 | M29: -1.7078554 | N29: 1.1480854 | O29: -1.4875682 | P29: 0.18046324 | Q29: -4.4226461 | R29: 1.0069352 | S29: -4.4226461 | T29: 1.0069352

Sheet Kalyan J Regression
B2: Regression Beta - 5 Years Monthly
B4: Kalyan Jewellery Monthly Returns | F4: NIFTY Returns | I4: Beta Drifting
L5: Beta 1 | M5: =SLOPE(D8:D64,G8:G64) -> 0.057413536
B6: Date | C6: Closing Price | D6: Returns | F6: Closing Price | G6: Return | I6: Levered Raw Beta | J6: =M7 -> 0.057413536 | L6: Beta 2 | M6: =_xlfn.COVARIANCE.S(D7:D64,G7:G64)/_xlfn.VAR.S(G7:G64) -> 0.057413536
B7: 44317 | C7: 66.26 | F7: 15582.8 | I7: Raw Beta Weight | J7: 0.75 | L7: Beta 3 | M7: =M27 -> 0.057413536
B8: 44348 | C8: 77.62 | D8: =C8/C7-1 -> 0.17144582 | F8: 15721.5 | G8: =F8/F7-1 -> 0.0089008394
B9: 44378 | C9: 70.38 | D9: =C9/C8-1 -> -0.093274929 | F9: 15763.05 | G9: =F9/F8-1 -> 0.0026428776 | I9: Market Beta | J9: 1
B10: 44409 | C10: 66.56 | D10: =C10/C9-1 -> -0.054276783 | F10: 17132.2 | G10: =F10/F9-1 -> 0.086858191 | I10: Market Beta Weight | J10: 0.25 | L10: SUMMARY OUTPUT
B11: 44440 | C11: 72.31 | D11: =C11/C10-1 -> 0.086388221 | F11: 17618.15 | G11: =F11/F10-1 -> 0.028364717
B12: 44470 | C12: 75.63 | D12: =C12/C11-1 -> 0.045913428 | F12: 17671.65 | G12: =F12/F11-1 -> 0.0030366412 | I12: Adjusted Beta | J12: =(J6*J7)+(J9*J10) -> 0.29306015 | L12: Regression Statistics
B13: 44501 | C13: 66.51 | D13: =C13/C12-1 -> -0.12058707 | F13: 16983.2 | G13: =F13/F12-1 -> -0.038957879 | L13: Multiple R | M13: 0.014804427
B14: 44531 | C14: 67.9 | D14: =C14/C13-1 -> 0.020899113 | F14: 17354.05 | G14: =F14/F13-1 -> 0.021836285 | L14: R Square | M14: 0.00021917105
B15: 44562 | C15: 66.01 | D15: =C15/C14-1 -> -0.027835052 | F15: 17339.85 | G15: =F15/F14-1 -> -0.0008182528 | L15: Adjusted R Square | M15: -0.017958662
B16: 44593 | C16: 58.47 | D16: =C16/C15-1 -> -0.11422512 | F16: 16793.9 | G16: =F16/F15-1 -> -0.031485278 | L16: Standard Error | M16: 0.13884886
B17: 44621 | C17: 58.28 | D17: =C17/C16-1 -> -0.0032495297 | F17: 17464.75 | G17: =F17/F16-1 -> 0.039946052 | L17: Observations | M17: 57
B18: 44652 | C18: 60.41 | D18: =C18/C17-1 -> 0.036547701 | F18: 17102.55 | G18: =F18/F17-1 -> -0.020738917
B19: 44682 | C19: 59.66 | D19: =C19/C18-1 -> -0.012415163 | F19: 16584.55 | G19: =F19/F18-1 -> -0.030287881 | L19: ANOVA
B20: 44713 | C20: 59.42 | D20: =C20/C19-1 -> -0.0040227958 | F20: 15780.25 | G20: =F20/F19-1 -> -0.048496944 | M20: df | N20: SS | O20: MS | P20: F | Q20: Significance F
B21: 44743 | C21: 64.53 | D21: =C21/C20-1 -> 0.08599798 | F21: 17158.25 | G21: =F21/F20-1 -> 0.087324345 | L21: Regression | M21: 1 | N21: 0.00023244794 | O21: 0.00023244794 | P21: 0.01205705 | Q21: 0.91296402
B22: 44774 | C22: 80.99 | D22: =C22/C21-1 -> 0.25507516 | F22: 17759.3 | G22: =F22/F21-1 -> 0.035029796 | L22: Residual | M22: 55 | N22: 1.0603453 | O22: 0.019279005
B23: 44805 | C23: 95.52 | D23: =C23/C22-1 -> 0.17940486 | F23: 17094.35 | G23: =F23/F22-1 -> -0.037442354 | L23: Total | M23: 56 | N23: 1.0605777
B24: 44835 | C24: 101.67 | D24: =C24/C23-1 -> 0.064384422 | F24: 18012.2 | G24: =F24/F23-1 -> 0.053693179
B25: 44866 | C25: 105.05 | D25: =C25/C24-1 -> 0.033244812 | F25: 18758.35 | G25: =F25/F24-1 -> 0.041424701 | M25: Coefficients | N25: Standard Error | O25: t Stat | P25: P-value | Q25: Lower 95% | R25: Upper 95% | S25: Lower 95.0% | T25: Upper 95.0%
B26: 44896 | C26: 125.53 | D26: =C26/C25-1 -> 0.19495478 | F26: 18105.3 | G26: =F26/F25-1 -> -0.03481383 | L26: Intercept | M26: 0.041510436 | N26: 0.018991924 | O26: 2.1856889 | P26: 0.033113925 | Q26: 0.0034497709 | R26: 0.079571102 | S26: 0.0034497709 | T26: 0.079571102
B27: 44927 | C27: 117 | D27: =C27/C26-1 -> -0.067951884 | F27: 17662.15 | G27: =F27/F26-1 -> -0.024476258 | L27: X Variable 1 | M27: 0.057413536 | N27: 0.52287005 | O27: 0.1098046 | P27: 0.91296402 | Q27: -0.99044146 | R27: 1.1052685 | S27: -0.99044146 | T27: 1.1052685
B28: 44958 | C28: 112.73 | D28: =C28/C27-1 -> -0.036495726 | F28: 17303.95 | G28: =F28/F27-1 -> -0.020280657
B29: 44986 | C29: 104.5 | D29: =C29/C28-1 -> -0.073006298 | F29: 17359.75 | G29: =F29/F28-1 -> 0.0032246973
B30: 45017 | C30: 101.87 | D30: =C30/C29-1 -> -0.025167464 | F30: 18065 | G30: =F30/F29-1 -> 0.040625585
B31: 45047 | C31: 104.8 | D31: =C31/C30-1 -> 0.028762148 | F31: 18534.4 | G31: =F31/F30-1 -> 0.025983947
B32: 45078 | C32: 145.86 | D32: =C32/C31-1 -> 0.39179389 | F32: 19189.05 | G32: =F32/F31-1 -> 0.035320809
B33: 45108 | C33: 173.29 | D33: =C33/C32-1 -> 0.18805704 | F33: 19753.8 | G33: =F33/F32-1 -> 0.029430847
B34: 45139 | C34: 249.77 | D34: =C34/C33-1 -> 0.4413411 | F34: 19253.8 | G34: =F34/F33-1 -> -0.025311586
B35: 45200 | C35: 287.21 | D35: =C35/C34-1 -> 0.14989791 | F35: 19638.3 | G35: =F35/F34-1 -> 0.019970084
B36: 45231 | C36: 323.43 | D36: =C36/C35-1 -> 0.12610982 | F36: 19079.6 | G36: =F36/F35-1 -> -0.028449509
B37: 45261 | C37: 352.28 | D37: =C37/C36-1 -> 0.089200136 | F37: 20133.15 | G37: =F37/F36-1 -> 0.055218663
B38: 45292 | C38: 348.4 | D38: =C38/C37-1 -> -0.011013966 | F38: 21731.4 | G38: =F38/F37-1 -> 0.079384001
B39: 45323 | C39: 394.81 | D39: =C39/C38-1 -> 0.13320896 | F39: 21725.7 | G39: =F39/F38-1 -> -0.00026229327
... B64: 46118 | C64: 420.35 | D64: =C64/C63-1 -> 0.065931279 | F64: 25178.65 | G64: =F64/F63-1 -> -0.0056080709
F65: 22331.4
F66: 22713.1
...

Sheet Thangamayil J Regression
B2: Regression Beta - 5 Years Monthly
B4: Thangamayil Monthly Returns | F4: NIFTY Returns | I4: Beta Drifting
L5: Beta 1 | M5: =SLOPE(D8:D67,G8:G67) -> 1.0684007
B6: Date | C6: Closing Price | D6: Returns | F6: Closing Price | G6: Return | I6: Levered Raw Beta | J6: =M7 -> 1.0684007 | L6: Beta 2 | M6: =_xlfn.COVARIANCE.S(D7:D67,G7:G67)/_xlfn.VAR.S(G7:G67) -> 1.0684007
B7: 44317 | C7: 382.07 | F7: 15582.8 | I7: Raw Beta Weight | J7: 0.75 | L7: Beta 3 | M7: =M29 -> 1.0684007
B8: 44348 | C8: 394.4 | D8: =C8/C7-1 -> 0.032271573 | F8: 15721.5 | G8: =F8/F7-1 -> 0.0089008394
B9: 44378 | C9: 422.93 | D9: =C9/C8-1 -> 0.072337728 | F9: 15763.05 | G9: =F9/F8-1 -> 0.0026428776 | I9: Market Beta | J9: 1
B10: 44409 | C10: 492.43 | D10: =C10/C9-1 -> 0.16432979 | F10: 17132.2 | G10: =F10/F9-1 -> 0.086858191 | I10: Market Beta Weight | J10: 0.25
B11: 44440 | C11: 539.13 | D11: =C11/C10-1 -> 0.094835814 | F11: 17618.15 | G11: =F11/F10-1 -> 0.028364717
B12: 44470 | C12: 628.59 | D12: =C12/C11-1 -> 0.165934 | F12: 17671.65 | G12: =F12/F11-1 -> 0.0030366412 | I12: Adjusted Beta | J12: =(J6*J7)+(J9*J10) -> 1.0513005 | L12: SUMMARY OUTPUT
B13: 44501 | C13: 672.47 | D13: =C13/C12-1 -> 0.069807028 | F13: 16983.2 | G13: =F13/F12-1 -> -0.038957879
B14: 44531 | C14: 666.99 | D14: =C14/C13-1 -> -0.0081490624 | F14: 17354.05 | G14: =F14/F13-1 -> 0.021836285 | L14: Regression Statistics
B15: 44562 | C15: 572.58 | D15: =C15/C14-1 -> -0.14154635 | F15: 17339.85 | G15: =F15/F14-1 -> -0.0008182528 | L15: Multiple R | M15: 0.27386735
B16: 44593 | C16: 554.04 | D16: =C16/C15-1 -> -0.032379755 | F16: 16793.9 | G16: =F16/F15-1 -> -0.031485278 | L16: R Square | M16: 0.075003325
B17: 44621 | C17: 530.74 | D17: =C17/C16-1 -> -0.042054725 | F17: 17464.75 | G17: =F17/F16-1 -> 0.039946052 | L17: Adjusted R Square | M17: 0.059055106
B18: 44652 | C18: 551.65 | D18: =C18/C17-1 -> 0.039397822 | F18: 17102.55 | G18: =F18/F17-1 -> -0.020738917 | L18: Standard Error | M18: 0.14388598
B19: 44682 | C19: 495.66 | D19: =C19/C18-1 -> -0.10149551 | F19: 16584.55 | G19: =F19/F18-1 -> -0.030287881 | L19: Observations | M19: 60
B20: 44713 | C20: 474.58 | D20: =C20/C19-1 -> -0.042529153 | F20: 15780.25 | G20: =F20/F19-1 -> -0.048496944
B21: 44743 | C21: 512.31 | D21: =C21/C20-1 -> 0.079501875 | F21: 17158.25 | G21: =F21/F20-1 -> 0.087324345 | L21: ANOVA
B22: 44774 | C22: 552.28 | D22: =C22/C21-1 -> 0.078019168 | F22: 17759.3 | G22: =F22/F21-1 -> 0.035029796 | M22: df | N22: SS | O22: MS | P22: F | Q22: Significance F
B23: 44805 | C23: 607.42 | D23: =C23/C22-1 -> 0.099840661 | F23: 17094.35 | G23: =F23/F22-1 -> -0.037442354 | L23: Regression | M23: 1 | N23: 0.097365541 | O23: 0.097365541 | P23: 4.7029281 | Q23: 0.034225209
B24: 44835 | C24: 477.05 | D24: =C24/C23-1 -> -0.21462909 | F24: 18012.2 | G24: =F24/F23-1 -> 0.053693179 | L24: Residual | M24: 58 | N24: 1.2007841 | O24: 0.020703175
B25: 44866 | C25: 499.08 | D25: =C25/C24-1 -> 0.046179646 | F25: 18758.35 | G25: =F25/F24-1 -> 0.041424701 | L25: Total | M25: 59 | N25: 1.2981497
B26: 44896 | C26: 535.19 | D26: =C26/C25-1 -> 0.07235313 | F26: 18105.3 | G26: =F26/F25-1 -> -0.03481383
B27: 44927 | C27: 519.1 | D27: =C27/C26-1 -> -0.030064089 | F27: 17662.15 | G27: =F27/F26-1 -> -0.024476258 | M27: Coefficients | N27: Standard Error | O27: t Stat | P27: P-value | Q27: Lower 95% | R27: Upper 95% | S27: Lower 95.0% | T27: Upper 95.0%
B28: 44958 | C28: 488.95 | D28: =C28/C27-1 -> -0.058081295 | F28: 17303.95 | G28: =F28/F27-1 -> -0.020280657 | L28: Intercept | M28: 0.040211089 | N28: 0.018911156 | O28: 2.1263158 | P28: 0.037744043 | Q28: 0.0023562977 | R28: 0.07806588 | S28: 0.0023562977 | T28: 0.07806588
B29: 44986 | C29: 494.2 | D29: =C29/C28-1 -> 0.010737294 | F29: 17359.75 | G29: =F29/F28-1 -> 0.0032246973 | L29: X Variable 1 | M29: 1.0684007 | N29: 0.49266307 | O29: 2.1686235 | P29: 0.034225209 | Q29: 0.082228451 | R29: 2.054573 | S29: 0.082228451 | T29: 2.054573
B30: 45017 | C30: 509.91 | D30: =C30/C29-1 -> 0.031788749 | F30: 18065 | G30: =F30/F29-1 -> 0.040625585
B31: 45047 | C31: 666.2 | D31: =C31/C30-1 -> 0.30650507 | F31: 18534.4 | G31: =F31/F30-1 -> 0.025983947
B32: 45078 | C32: 746.91 | D32: =C32/C31-1 -> 0.1211498 | F32: 19189.05 | G32: =F32/F31-1 -> 0.035320809
B33: 45108 | C33: 1253.91 | D33: =C33/C32-1 -> 0.67879664 | F33: 19753.8 | G33: =F33/F32-1 -> 0.029430847
B34: 45139 | C34: 1221.83 | D34: =C34/C33-1 -> -0.025583973 | F34: 19253.8 | G34: =F34/F33-1 -> -0.025311586
B35: 45170 | C35: 1221.38 | D35: =C35/C34-1 -> -0.00036830001 | F35: 19638.3 | G35: =F35/F34-1 -> 0.019970084
B36: 45200 | C36: 1412.32 | D36: =C36/C35-1 -> 0.15633136 | F36: 19079.6 | G36: =F36/F35-1 -> -0.028449509
B37: 45231 | C37: 1359.99 | D37: =C37/C36-1 -> -0.037052509 | F37: 20133.15 | G37: =F37/F36-1 -> 0.055218663
B38: 45261 | C38: 1472.34 | D38: =C38/C37-1 -> 0.082610902 | F38: 21731.4 | G38: =F38/F37-1 -> 0.079384001
B39: 45292 | C39: 1337.88 | D39: =C39/C38-1 -> -0.091324015 | F39: 21725.7 | G39: =F39/F38-1 -> -0.00026229327
B40: 45323 | C40: 1352.15 | D40: =C40/C39-1 -> 0.010666129 | F40: 21982.8 | G40: =F40/F39-1 -> 0.011833911
B41: 45352 | C41: 1275.05 | D41: =C41/C40-1 -> -0.057020301 | F41: 22326.9 | G41: =F41/F40-1 -> 0.015653147
... B67: 46118 | C67: 3752.9 | D67: =C67/C66-1 -> 0.059004458 | F67: 22968.25 | G67: =F67/F66-1 -> 0.011233605
...

Sheet P N Gadgil J Regression
B2: Regression Beta - 5 Years Monthly
B4: P N Gadgil Jewel Monthly Returns | F4: NIFTY Returns | I4: Beta Drifting | V4: Date | W4: Adj Close
L5: Beta 1 | M5: =SLOPE(D8:D113,G8:G113) -> -0.42304575
B6: Date | C6: Closing Price | D6: Returns | F6: Closing Price | G6: Return | I6: Levered Raw Beta | J6: =M7 -> -0.42304575 | L6: Beta 2 | M6: =_xlfn.COVARIANCE.S(D7:D113,G7:G113)/_xlfn.VAR.S(G7:G113) -> -0.42304575
B7: 45536 | C7: 749.15 | F7: 15582.8 | I7: Raw Beta Weight | J7: 0.75 | L7: Beta 3 | M7: =M29 -> -0.42304575
B8: 45566 | C8: 715.6 | D8: =C8/C7-1 -> -0.044784089 | F8: 15721.5 | G8: =F8/F7-1 -> 0.0089008394
B9: 45597 | C9: 681.2 | D9: =C9/C8-1 -> -0.048071548 | F9: 15763.05 | G9: =F9/F8-1 -> 0.0026428776 | I9: Market Beta | J9: 1
B10: 45627 | C10: 665.35 | D10: =C10/C9-1 -> -0.023267763 | F10: 17132.2 | G10: =F10/F9-1 -> 0.086858191 | I10: Market Beta Weight | J10: 0.25
B11: 45658 | C11: 564.8 | D11: =C11/C10-1 -> -0.15112347 | F11: 17618.15 | G11: =F11/F10-1 -> 0.028364717
B12: 45689 | C12: 537.95 | D12: =C12/C11-1 -> -0.047538952 | F12: 17671.65 | G12: =F12/F11-1 -> 0.0030366412 | I12: Adjusted Beta | J12: =(J6*J7)+(J9*J10) -> -0.067284316 | L12: SUMMARY OUTPUT
B13: 45717 | C13: 505.65 | D13: =C13/C12-1 -> -0.060042755 | F13: 16983.2 | G13: =F13/F12-1 -> -0.038957879
B14: 45748 | C14: 511 | D14: =C14/C13-1 -> 0.010580441 | F14: 17354.05 | G14: =F14/F13-1 -> 0.021836285 | L14: Regression Statistics
B15: 45778 | C15: 548.5 | D15: =C15/C14-1 -> 0.073385519 | F15: 17339.85 | G15: =F15/F14-1 -> -0.0008182528 | L15: Multiple R | M15: 0.29463052
B16: 45809 | C16: 580.7 | D16: =C16/C15-1 -> 0.058705561 | F16: 16793.9 | G16: =F16/F15-1 -> -0.031485278 | L16: R Square | M16: 0.086807143
B17: 45839 | C17: 584 | D17: =C17/C16-1 -> 0.0056827966 | F17: 17464.75 | G17: =F17/F16-1 -> 0.039946052 | L17: Adjusted R Square | M17: 0.036074206
B18: 45870 | C18: 572.15 | D18: =C18/C17-1 -> -0.020291096 | F18: 17102.55 | G18: =F18/F17-1 -> -0.020738917 | L18: Standard Error | M18: 0.058203981
B19: 45901 | C19: 603.5 | D19: =C19/C18-1 -> 0.054793323 | F19: 16584.55 | G19: =F19/F18-1 -> -0.030287881 | L19: Observations | M19: 20
B20: 45931 | C20: 647.7 | D20: =C20/C19-1 -> 0.073239437 | F20: 15780.25 | G20: =F20/F19-1 -> -0.048496944
B21: 45962 | C21: 629.65 | D21: =C21/C20-1 -> -0.02786784 | F21: 17158.25 | G21: =F21/F20-1 -> 0.087324345 | L21: ANOVA
B22: 45992 | C22: 607.45 | D22: =C22/C21-1 -> -0.035257683 | F22: 17759.3 | G22: =F22/F21-1 -> 0.035029796 | M22: df | N22: SS | O22: MS | P22: F | Q22: Significance F
B23: 46023 | C23: 549.8 | D23: =C23/C22-1 -> -0.09490493 | F23: 17094.35 | G23: =F23/F22-1 -> -0.037442354 | L23: Regression | M23: 1 | N23: 0.0057965667 | O23: 0.0057965667 | P23: 1.7110609 | Q23: 0.20730704
B24: 46054 | C24: 552 | D24: =C24/C23-1 -> 0.0040014551 | F24: 18012.2 | G24: =F24/F23-1 -> 0.053693179 | L24: Residual | M24: 18 | N24: 0.06097866 | O24: 0.0033877034
B25: 46082 | C25: 530.95 | D25: =C25/C24-1 -> -0.038134058 | F25: 18758.35 | G25: =F25/F24-1 -> 0.041424701 | L25: Total | M25: 19 | N25: 0.066775227
B26: 46113 | C26: 569 | D26: =C26/C25-1 -> 0.071663998 | F26: 18105.3 | G26: =F26/F25-1 -> -0.03481383
B27: 46118 | C27: 578.75 | D27: =C27/C26-1 -> 0.017135325 | F27: 17662.15 | G27: =F27/F26-1 -> -0.024476258 | M27: Coefficients | N27: Standard Error | O27: t Stat | P27: P-value | Q27: Lower 95% | R27: Upper 95% | S27: Lower 95.0% | T27: Upper 95.0%
L28: Intercept | M28: -0.0081109209 | N28: 0.013214525 | O28: -0.61378829 | P28: 0.54703464 | Q28: -0.035873608 | R28: 0.019651766 | S28: -0.035873608 | T28: 0.019651766
L29: X Variable 1 | M29: -0.42304575 | N29: 0.32341087 | O29: -1.3080753 | P29: 0.20730704 | Q29: -1.1025068 | R29: 0.25641527 | S29: -1.1025068 | T29: 0.25641527

Sheet PC Jeweller Regression
B2: Regression Beta - 5 Years Monthly
B4: PC Jeweller Monthly Returns | F4: NIFTY Returns | I4: Beta Drifting
L5: Beta 1 | M5: =SLOPE(D8:D113,G8:G113) -> 2.5407188
B6: Date | C6: Closing Price | D6: Returns | F6: Closing Price | G6: Return | I6: Levered Raw Beta | J6: =M7 -> 2.5407188 | L6: Beta 2 | M6: =_xlfn.COVARIANCE.S(D7:D113,G7:G113)/_xlfn.VAR.S(G7:G113) -> 2.5407188
B7: 44317 | C7: 2.7 | F7: 15582.8 | I7: Raw Beta Weight | J7: 0.75 | L7: Beta 3 | M7: =M29 -> 2.5407188
B8: 44348 | C8: 2.68 | D8: =C8/C7-1 -> -0.0074074074 | F8: 15721.5 | G8: =F8/F7-1 -> 0.0089008394
B9: 44378 | C9: 2.45 | D9: =C9/C8-1 -> -0.085820896 | F9: 15763.05 | G9: =F9/F8-1 -> 0.0026428776 | I9: Market Beta | J9: 1
B10: 44409 | C10: 2.28 | D10: =C10/C9-1 -> -0.069387755 | F10: 17132.2 | G10: =F10/F9-1 -> 0.086858191 | I10: Market Beta Weight | J10: 0.25
B11: 44440 | C11: 2.66 | D11: =C11/C10-1 -> 0.16666667 | F11: 17618.15 | G11: =F11/F10-1 -> 0.028364717
B12: 44470 | C12: 2.76 | D12: =C12/C11-1 -> 0.037593985 | F12: 17671.65 | G12: =F12/F11-1 -> 0.0030366412 | I12: Adjusted Beta | J12: =(J6*J7)+(J9*J10) -> 2.1555391 | L12: SUMMARY OUTPUT
B13: 44501 | C13: 2.35 | D13: =C13/C12-1 -> -0.14855072 | F13: 16983.2 | G13: =F13/F12-1 -> -0.038957879
B14: 44531 | C14: 2.69 | D14: =C14/C13-1 -> 0.14468085 | F14: 17354.05 | G14: =F14/F13-1 -> 0.021836285 | L14: Regression Statistics
B15: 44562 | C15: 2.63 | D15: =C15/C14-1 -> -0.022304833 | F15: 17339.85 | G15: =F15/F14-1 -> -0.0008182528 | L15: Multiple R | M15: 0.37595635
B16: 44593 | C16: 2.02 | D16: =C16/C15-1 -> -0.23193916 | F16: 16793.9 | G16: =F16/F15-1 -> -0.031485278 | L16: R Square | M16: 0.14134318
B17: 44621 | C17: 2.09 | D17: =C17/C16-1 -> 0.034653465 | F17: 17464.75 | G17: =F17/F16-1 -> 0.039946052 | L17: Adjusted R Square | M17: 0.12627902
B18: 44652 | C18: 2.2 | D18: =C18/C17-1 -> 0.052631579 | F18: 17102.55 | G18: =F18/F17-1 -> -0.020738917 | L18: Standard Error | M18: 0.24222439
B19: 44682 | C19: 2.02 | D19: =C19/C18-1 -> -0.081818182 | F19: 16584.55 | G19: =F19/F18-1 -> -0.030287881 | L19: Observations | M19: 59
B20: 44713 | C20: 2.31 | D20: =C20/C19-1 -> 0.14356436 | F20: 15780.25 | G20: =F20/F19-1 -> -0.048496944
B21: 44743 | C21: 4.68 | D21: =C21/C20-1 -> 1.025974 | F21: 17158.25 | G21: =F21/F20-1 -> 0.087324345 | L21: ANOVA
B22: 44774 | C22: 7.14 | D22: =C22/C21-1 -> 0.52564103 | F22: 17759.3 | G22: =F22/F21-1 -> 0.035029796 | M22: df | N22: SS | O22: MS | P22: F | Q22: Significance F
B23: 44805 | C23: 8.39 | D23: =C23/C22-1 -> 0.17507003 | F23: 17094.35 | G23: =F23/F22-1 -> -0.037442354 | L23: Regression | M23: 1 | N23: 0.55051078 | O23: 0.55051078 | P23: 9.3827485 | Q23: 0.0033411863
B24: 44835 | C24: 10.39 | D24: =C24/C23-1 -> 0.23837902 | F24: 18012.2 | G24: =F24/F23-1 -> 0.053693179 | L24: Residual | M24: 57 | N24: 3.3443414 | O24: 0.058672656
B25: 44866 | C25: 7.89 | D25: =C25/C24-1 -> -0.24061598 | F25: 18758.35 | G25: =F25/F24-1 -> 0.041424701 | L25: Total | M25: 58 | N25: 3.8948522
B26: 44896 | C26: 8.34 | D26: =C26/C25-1 -> 0.057034221 | F26: 18105.3 | G26: =F26/F25-1 -> -0.03481383
B27: 44927 | C27: 5.05 | D27: =C27/C26-1 -> -0.39448441 | F27: 17662.15 | G27: =F27/F26-1 -> -0.024476258 | M27: Coefficients | N27: Standard Error | O27: t Stat | P27: P-value | Q27: Lower 95% | R27: Upper 95% | S27: Lower 95.0% | T27: Upper 95.0%
B28: 44958 | C28: 2.71 | D28: =C28/C27-1 -> -0.46336634 | F28: 17303.95 | G28: =F28/F27-1 -> -0.020280657 | L28: Intercept | M28: 0.028790518 | N28: 0.03208478 | O28: 0.89732635 | P28: 0.37331934 | Q28: -0.035458145 | R28: 0.093039182 | S28: -0.035458145 | T28: 0.093039182
B29: 44986 | C29: 2.67 | D29: =C29/C28-1 -> -0.014760148 | F29: 17359.75 | G29: =F29/F28-1 -> 0.0032246973 | L29: X Variable 1 | M29: 2.5407188 | N29: 0.82945257 | O29: 3.0631272 | P29: 0.0033411863 | Q29: 0.87976863 | R29: 4.2016689 | S29: 0.87976863 | T29: 4.2016689
B30: 45017 | C30: 2.55 | D30: =C30/C29-1 -> -0.04494382 | F30: 18065 | G30: =F30/F29-1 -> 0.040625585
B31: 45047 | C31: 2.35 | D31: =C31/C30-1 -> -0.078431373 | F31: 18534.4 | G31: =F31/F30-1 -> 0.025983947
B32: 45078 | C32: 2.63 | D32: =C32/C31-1 -> 0.11914894 | F32: 19189.05 | G32: =F32/F31-1 -> 0.035320809
B33: 45108 | C33: 2.93 | D33: =C33/C32-1 -> 0.11406844 | F33: 19753.8 | G33: =F33/F32-1 -> 0.029430847
B34: 45139 | C34: 2.66 | D34: =C34/C33-1 -> -0.092150171 | F34: 19253.8 | G34: =F34/F33-1 -> -0.025311586
B35: 45170 | C35: 2.62 | D35: =C35/C34-1 -> -0.015037594 | F35: 19638.3 | G35: =F35/F34-1 -> 0.019970084
B36: 45200 | C36: 2.94 | D36: =C36/C35-1 -> 0.1221374 | F36: 19079.6 | G36: =F36/F35-1 -> -0.028449509
B37: 45231 | C37: 2.81 | D37: =C37/C36-1 -> -0.044217687 | F37: 20133.15 | G37: =F37/F36-1 -> 0.055218663
B38: 45261 | C38: 4.67 | D38: =C38/C37-1 -> 0.66192171 | F38: 21731.4 | G38: =F38/F37-1 -> 0.079384001
B39: 45292 | C39: 5.52 | D39: =C39/C38-1 -> 0.18201285 | F39: 21725.7 | G39: =F39/F38-1 -> -0.00026229327
B40: 45323 | C40: 5.78 | D40: =C40/C39-1 -> 0.047101449 | F40: 21982.8 | G40: =F40/F39-1 -> 0.011833911
B41: 45352 | C41: 5.38 | D41: =C41/C40-1 -> -0.069204152 | F41: 22326.9 | G41: =F41/F40-1 -> 0.015653147
... B66: 46118 | C66: 8.46 | D66: =C66/C65-1 -> 0.03045067 | F66: 22713.1 | G66: =F66/F65-1 -> 0.017092524

Sheet Rm
B2: Return on Markets
B4: Year | C4: Annual
B5: 2000 | C5: -0.1465 | E5: Average Return | G5: =AVERAGE(C5:C30) -> 0.15149231
B6: 2001 | C6: -0.1618 | E6: Dividend Yield | G6: 1.16% 1
B7: 2002 | C7: 0.0325 | E7: Total Market Return | G7: =SUM(G5:G6) -> 0.15149231
B8: 2003 | C8: 0.719
B9: 2004 | C9: 0.1068
B10: 2005 | C10: 0.3634
B11: 2006 | C11: 0.3983
B12: 2007 | C12: 0.5477
B13: 2008 | C13: -0.5179
B14: 2009 | C14: 0.7576
B15: 2010 | C15: 0.1795
B16: 2011 | C16: -0.2462
B17: 2012 | C17: 0.277
B18: 2013 | C18: 0.0676
B19: 2014 | C19: 0.3139
... B30: 2025 | C30: 0.1051

Sheet Beta - Comps
B2: S.No. | C2: Name | D2: CMP Rs. | E2: Mar Cap Rs.Cr. | F2: Debt Rs.Cr. | G2: Debt / Eq
B3: 1 | C3: Titan Company | D3: 4246.1 | E3: 376912.29 | F3: 12465 | G3: 0.97
B4: 2 | C4: Kalyan Jewellers | D4: 420.35 | E4: 43400.23 | F4: 5334.96 | G4: 1
B5: 3 | C5: Thangamayil Jew. | D5: 3752.9 | E5: 11659.68 | F5: 1124.35 | G5: 0.96
B6: 4 | C6: P N Gadgil Jewe. | D6: 578.75 | E6: 7904.82 | F6: 1291.13 | G6: 0.76
B7: 5 | C7: PC Jeweller | D7: 8.46 | E7: 7054.05 | F7: 1594.49 | G7: 0.22
B8: 6 | C8: Bluestone Jewel | D8: 427.45 | E8: 6494.97 | F8: 1889.28 | G8: 1.12

Sheet Financials>

Sheet HistoricalFS
B2: ="Historical Financial Statement - "&'Data Sheet'!B1 -> Historical Financial Statement - TITAN COMPANY LTD
B3: Years | C3: ='Data Sheet'!B16 -> 42460 | D3: ='Data Sheet'!C16 -> 42825 | E3: ='Data Sheet'!D16 -> 43190 | F3: ='Data Sheet'!E16 -> 43555 | G3: ='Data Sheet'!F16 -> 43921 | H3: ='Data Sheet'!G16 -> 44286 | I3: ='Data Sheet'!H16 -> 44651 | J3: ='Data Sheet'!I16 -> 45016 | ... L3: ='Data Sheet'!K16 -> 45747 | M3: LTM
A5: # | B5: Income Statement
B6: Sales | C6: =IFERROR('Data Sheet'!B17,0) -> 11275.89 | D6: =IFERROR('Data Sheet'!C17,0) -> 13260.83 | E6: =IFERROR('Data Sheet'!D17,0) -> 16119.77 | F6: =IFERROR('Data Sheet'!E17,0) -> 19778.52 | G6: =IFERROR('Data Sheet'!F17,0) -> 21052 | H6: =IFERROR('Data Sheet'!G17,0) -> 21644 | I6: =IFERROR('Data Sheet'!H17,0) -> 28799 | J6: =IFERROR('Data Sheet'!I17,0) -> 40575 | ... L6: =IFERROR('Data Sheet'!K17,0) -> 60456 | M6: =IFERROR(SUM('Data Sheet'!H42:K42),0) -> 75580
B7: Sales Growth | C7: - | D7: =D6/C6-1 -> 0.176034 | E7: =E6/D6-1 -> 0.21559284 | F7: =F6/E6-1 -> 0.22697284 | G7: =G6/F6-1 -> 0.064387022 | H7: =H6/G6-1 -> 0.028120844 | I7: =I6/H6-1 -> 0.3305766 | J7: =J6/I6-1 -> 0.40890309 | K7: =K6/J6-1 -> 0.25900185 | ... M7: =M6/L6-1 -> 0.25016541
B9: COGS | C9: =IFERROR(SUM('Data Sheet'!B18,'Data Sheet'!B20:B22)-1*'Data Sheet'!B19,0) -> 9183.33 | D9: =IFERROR(SUM('Data Sheet'!C18,'Data Sheet'!C20:C22)-1*'Data Sheet'!C19,0) -> 10606.01 | E9: =IFERROR(SUM('Data Sheet'!D18,'Data Sheet'!D20:D22)-1*'Data Sheet'!D19,0) -> 12762.63 | F9: =IFERROR(SUM('Data Sheet'!E18,'Data Sheet'!E20:E22)-1*'Data Sheet'!E19,0) -> 15660.48 | G9: =IFERROR(SUM('Data Sheet'!F18,'Data Sheet'!F20:F22)-1*'Data Sheet'!F19,0) -> 16626 | H9: =IFERROR(SUM('Data Sheet'!G18,'Data Sheet'!G20:G22)-1*'Data Sheet'!G19,0) -> 17661 | I9: =IFERROR(SUM('Data Sheet'!H18,'Data Sheet'!H20:H22)-1*'Data Sheet'!H19,0) -> 23225 | J9: =IFERROR(SUM('Data Sheet'!I18,'Data Sheet'!I20:I22)-1*'Data Sheet'!I19,0) -> 32295 | ... L9: =IFERROR(SUM('Data Sheet'!K18,'Data Sheet'!K20:K22)-1*'Data Sheet'!K19,0) -> 50024 | M9: =IFERROR(SUM('Data Sheet'!H43:K43),0) -> 67625
B10: COGS % Sales | C10: =C9/C6 -> 0.81442174 | D10: =D9/D6 -> 0.79979986 | E10: =E9/E6 -> 0.79173772 | F10: =F9/F6 -> 0.79179231 | G10: =G9/G6 -> 0.78975869 | H10: =H9/H6 -> 0.81597671 | I10: =I9/I6 -> 0.80645161 | J10: =J9/J6 -> 0.79593346 | ... M10: =M9/M6 -> 0.89474729
B12: Gross Profit | C12: =C6-C9 -> 2092.56 | D12: =D6-D9 -> 2654.82 | E12: =E6-E9 -> 3357.14 | F12: =F6-F9 -> 4118.04 | G12: =G6-G9 -> 4426 | H12: =H6-H9 -> 3983 | I12: =I6-I9 -> 5574 | J12: =J6-J9 -> 8280 | ... M12: =M6-M9 -> 7955
B13: Gross Margins | C13: =C12/C6 -> 0.18557826 | D13: =D12/D6 -> 0.20020014 | E13: =E12/E6 -> 0.20826228 | F13: =F12/F6 -> 0.20820769 | G13: =G12/G6 -> 0.21024131 | H13: =H12/H6 -> 0.18402329 | I13: =I12/I6 -> 0.19354839 | J13: =J12/J6 -> 0.20406654 | ... M13: =M12/M6 -> 0.10525271
B15: Selling & General Expenses | C15: =IFERROR(SUM('Data Sheet'!B23:B24),0) -> 1153.23 | D15: =IFERROR(SUM('Data Sheet'!C23:C24),0) -> 1490.92 | E15: =IFERROR(SUM('Data Sheet'!D23:D24),0) -> 1712.94 | F15: =IFERROR(SUM('Data Sheet'!E23:E24),0) -> 2124.25 | G15: =IFERROR(SUM('Data Sheet'!F23:F24),0) -> 1963 | H15: =IFERROR(SUM('Data Sheet'!G23:G24),0) -> 2258 | I15: =IFERROR(SUM('Data Sheet'!H23:H24),0) -> 2230 | J15: =IFERROR(SUM('Data Sheet'!I23:I24),0) -> 3398 | ... L15: =IFERROR(SUM('Data Sheet'!K23:K24),0) -> 4738
B16: S&G Exp % Sales | C16: =C15/C6 -> 0.10227397 | D16: =D15/D6 -> 0.11243037 | E16: =E15/E6 -> 0.1062633 | F16: =F15/F6 -> 0.10740187 | G16: =G15/G6 -> 0.093245297 | H16: =H15/H6 -> 0.10432452 | I16: =I15/I6 -> 0.077433244 | J16: =J15/J6 -> 0.083746149 | ... M16: =M15/M6 -> 0
B18: EBITDA | C18: =C12-C15 -> 939.33 | D18: =D12-D15 -> 1163.9 | E18: =E12-E15 -> 1644.2 | F18: =F12-F15 -> 1993.79 | G18: =G12-G15 -> 2463 | H18: =H12-H15 -> 1725 | I18: =I12-I15 -> 3344 | J18: =J12-J15 -> 4882 | ... M18: =M12-M15 -> 7955
B19: EBITDA Margins | C19: =C18/C6 -> 0.083304289 | D19: =D18/D6 -> 0.08776977 | E19: =E18/E6 -> 0.10199897 | F19: =F18/F6 -> 0.10080582 | G19: =G18/G6 -> 0.11699601 | H19: =H18/H6 -> 0.079698762 | I19: =I18/I6 -> 0.11611514 | J19: =J18/J6 -> 0.12032039 | ... M19: =M18/M6 -> 0.10525271
B21: Interest | C21: =IFERROR('Data Sheet'!B27,0) -> 42.36 | D21: =IFERROR('Data Sheet'!C27,0) -> 37.74 | E21: =IFERROR('Data Sheet'!D27,0) -> 52.92 | F21: =IFERROR('Data Sheet'!E27,0) -> 52.54 | G21: =IFERROR('Data Sheet'!F27,0) -> 166 | H21: =IFERROR('Data Sheet'!G27,0) -> 203 | I21: =IFERROR('Data Sheet'!H27,0) -> 218 | J21: =IFERROR('Data Sheet'!I27,0) -> 300 | ... L21: =IFERROR('Data Sheet'!K27,0) -> 953 | M21: =IFERROR(SUM('Data Sheet'!H46:K46),0) -> 1082
B22: Interest % Sales | C22: =C21/C6 -> 0.0037566879 | D22: =D21/D6 -> 0.0028459757 | E22: =E21/E6 -> 0.0032829253 | F22: =F21/F6 -> 0.0026564172 | G22: =G21/G6 -> 0.0078852366 | H22: =H21/H6 -> 0.0093790427 | I22: =I21/I6 -> 0.0075697073 | J22: =J21/J6 -> 0.0073937153 | ... M22: =M21/M6 -> 0.014315957
B24: Depreciation | C24: =IFERROR('Data Sheet'!B26,0) -> 98.19 | D24: =IFERROR('Data Sheet'!C26,0) -> 110.53 | E24: =IFERROR('Data Sheet'!D26,0) -> 131.43 | F24: =IFERROR('Data Sheet'!E26,0) -> 162.84 | G24: =IFERROR('Data Sheet'!F26,0) -> 348 | H24: =IFERROR('Data Sheet'!G26,0) -> 375 | I24: =IFERROR('Data Sheet'!H26,0) -> 399 | J24: =IFERROR('Data Sheet'!I26,0) -> 441 | ... L24: =IFERROR('Data Sheet'!K26,0) -> 693 | M24: =IFERROR(SUM('Data Sheet'!H45:K45),0) -> 763
B25: Depreciation % Sales | C25: =C24/C6 -> 0.0087079601 | D25: =D24/D6 -> 0.008335074 | E25: =E24/E6 -> 0.0081533421 | F25: =F24/F6 -> 0.0082331742 | G25: =G24/G6 -> 0.016530496 | H25: =H24/H6 -> 0.017325818 | I25: =I24/I6 -> 0.013854648 | J25: =J24/J6 -> 0.010868762 | ... M25: =M24/M6 -> 0.010095263
B27: Earnings Before Tax | C27: =IFERROR(C18-SUM(C24,C21),0) -> 798.78 | D27: =IFERROR(D18-SUM(D24,D21),0) -> 1015.63 | E27: =IFERROR(E18-SUM(E24,E21),0) -> 1459.85 | F27: =IFERROR(F18-SUM(F24,F21),0) -> 1778.41 | G27: =IFERROR(G18-SUM(G24,G21),0) -> 1949 | H27: =IFERROR(H18-SUM(H24,H21),0) -> 1147 | I27: =IFERROR(I18-SUM(I24,I21),0) -> 2727 | J27: =IFERROR(J18-SUM(J24,J21),0) -> 4141 | ... M27: =IFERROR(M18-SUM(M24,M21),0) -> 6110
B28: EBT % Sales | C28: =C27/C9 -> 0.08698152 | D28: =D27/D9 -> 0.095759857 | E28: =E27/E9 -> 0.11438473 | F28: =F27/F9 -> 0.11356038 | G28: =G27/G9 -> 0.11722603 | H28: =H27/H9 -> 0.06494536 | I28: =I27/I9 -> 0.11741658 | J28: =J27/J9 -> 0.12822418 | ... M28: =M27/M9 -> 0.090351201
B30: Tax | C30: =IFERROR('Data Sheet'!B29,0) -> 191.59 | D30: =IFERROR('Data Sheet'!C29,0) -> 275.97 | E30: =IFERROR('Data Sheet'!D29,0) -> 427.87 | F30: =IFERROR('Data Sheet'!E29,0) -> 568.24 | G30: =IFERROR('Data Sheet'!F29,0) -> 609 | H30: =IFERROR('Data Sheet'!G29,0) -> 353 | I30: =IFERROR('Data Sheet'!H29,0) -> 706 | J30: =IFERROR('Data Sheet'!I29,0) -> 1173 | ... L30: =IFERROR('Data Sheet'!K29,0) -> 1198 | M30: =IFERROR(SUM('Data Sheet'!H48:K48),0) -> 1677
B31: Effective Tax Rate | C31: =C30/C27 -> 0.23985328 | D31: =D30/D27 -> 0.27172297 | E31: =E30/E27 -> 0.29309176 | F31: =F30/F27 -> 0.31952137 | G31: =G30/G27 -> 0.31246793 | H31: =H30/H27 -> 0.30775937 | I31: =I30/I27 -> 0.25889256 | J31: =J30/J27 -> 0.28326491 | ... M31: =M30/M27 -> 0.27446809
B33: Net Profit | C33: =IFERROR(C27-C30,0) -> 607.19 | D33: =D27-D30 -> 739.66 | E33: =E27-E30 -> 1031.98 | F33: =F27-F30 -> 1210.17 | G33: =G27-G30 -> 1340 | H33: =H27-H30 -> 794 | I33: =I27-I30 -> 2021 | J33: =J27-J30 -> 2968 | K33: =K27-K30 -> 2962 | ... M33: =M27-M30 -> 4433
B34: Net Margins | C34: =C33/C6 -> 0.053848521 | D34: =D33/D6 -> 0.055777806 | E34: =E33/E6 -> 0.064019524 | F34: =F33/F6 -> 0.061186075 | G34: =G33/G6 -> 0.06365191 | H34: =H33/H6 -> 0.036684532 | I34: =I33/I6 -> 0.070176048 | J34: =J33/J6 -> 0.07314849 | ... M34: =M33/M6 -> 0.058653083
B36: No of Equity Shares | C36: =IFERROR('Data Sheet'!B93,0) -> 88.78 | D36: =IFERROR('Data Sheet'!C93,0) -> 88.78 | E36: =IFERROR('Data Sheet'!D93,0) -> 88.78 | F36: =IFERROR('Data Sheet'!E93,0) -> 88.78 | G36: =IFERROR('Data Sheet'!F93,0) -> 88.78 | H36: =IFERROR('Data Sheet'!G93,0) -> 88.78 | I36: =IFERROR('Data Sheet'!H93,0) -> 88.78 | J36: =IFERROR('Data Sheet'!I93,0) -> 88.78 | ... L36: =IFERROR('Data Sheet'!K93,0) -> 88.78 | M36: =L36 -> 88.78
B38: Earning Per Share | C38: =IFERROR(C33/C36,0) -> 6.8392656 | D38: =IFERROR(D33/D36,0) -> 8.3313809 | E38: =IFERROR(E33/E36,0) -> 11.624014 | F38: =IFERROR(F33/F36,0) -> 13.631111 | G38: =IFERROR(G33/G36,0) -> 15.09349 | H38: =IFERROR(H33/H36,0) -> 8.9434557 | I38: =IFERROR(I33/I36,0) -> 22.764136 | J38: =IFERROR(J33/J36,0) -> 33.430953 | ... M38: =IFERROR(M33/M36,0) -> 49.932417
B39: EPS Growth% | D39: =IFERROR(D38/C38-1,0) -> 0.21816894 | E39: =IFERROR(E38/D38-1,0) -> 0.39520861 | F39: =IFERROR(F38/E38-1,0) -> 0.17266807 | G39: =IFERROR(G38/F38-1,0) -> 0.10728245 | H39: =IFERROR(H38/G38-1,0) -> -0.40746269 | I39: =IFERROR(I38/H38-1,0) -> 1.5453401 | J39: =IFERROR(J38/I38-1,0) -> 0.46857991 | K39: =IFERROR(K38/J38-1,0) -> -0.0020215633 | ... M39: =IFERROR(M38/L38-1,0) -> 0.5554386
B41: Dividend Per Share | C41: =IFERROR('Data Sheet'!B31/HistoricalFS!C36,0) -> 2.2000451 | D41: =IFERROR('Data Sheet'!C31/HistoricalFS!D36,0) -> 2.6000225 | E41: =IFERROR('Data Sheet'!D31/HistoricalFS!E36,0) -> 3.7499437 | F41: =IFERROR('Data Sheet'!E31/HistoricalFS!F36,0) -> 5 | G41: =IFERROR('Data Sheet'!F31/HistoricalFS!G36,0) -> 4.0099121 | H41: =IFERROR('Data Sheet'!G31/HistoricalFS!H36,0) -> 4.0099121 | I41: =IFERROR('Data Sheet'!H31/HistoricalFS!I36,0) -> 7.5185853 | J41: =IFERROR('Data Sheet'!I31/HistoricalFS!J36,0) -> 10.02478 | ... L41: =IFERROR('Data Sheet'!K31/HistoricalFS!L36,0) -> 11.027258
B42: Dividend Payout ratio | C42: =IFERROR(C41/C38,0) -> 0.32167855 | D42: =IFERROR(D41/D38,0) -> 0.31207582 | E42: =IFERROR(E41/E38,0) -> 0.32260315 | F42: =IFERROR(F41/F38,0) -> 0.36680797 | G42: =IFERROR(G41/G38,0) -> 0.26567164 | H42: =IFERROR(H41/H38,0) -> 0.44836272 | I42: =IFERROR(I41/I38,0) -> 0.33028204 | J42: =IFERROR(J41/J38,0) -> 0.29986523 | ... L42: =IFERROR(L41/L38,0) -> 0.34350877
B44: Retained Earnings | C44: =IFERROR(IF(C38>C41,1-C42,0),0) -> 0.67832145 | D44: =IFERROR(IF(D38>D41,1-D42,0),0) -> 0.68792418 | E44: =IFERROR(IF(E38>E41,1-E42,0),0) -> 0.67739685 | F44: =IFERROR(IF(F38>F41,1-F42,0),0) -> 0.63319203 | G44: =IFERROR(IF(G38>G41,1-G42,0),0) -> 0.73432836 | H44: =IFERROR(IF(H38>H41,1-H42,0),0) -> 0.55163728 | I44: =IFERROR(IF(I38>I41,1-I42,0),0) -> 0.66971796 | J44: =IFERROR(IF(J38>J41,1-J42,0),0) -> 0.70013477 | ... L44: =IFERROR(IF(L38>L41,1-L42,0),0) -> 0.65649123
A46: # | B46: Balance Sheet
B47: Equity Share Capital | C47: =IFERROR('Data Sheet'!B57,0) -> 88.78 | D47: =IFERROR('Data Sheet'!C57,0) -> 88.78 | E47: =IFERROR('Data Sheet'!D57,0) -> 88.78 | F47: =IFERROR('Data Sheet'!E57,0) -> 88.78 | G47: =IFERROR('Data Sheet'!F57,0) -> 89 | H47: =IFERROR('Data Sheet'!G57,0) -> 89 | I47: =IFERROR('Data Sheet'!H57,0) -> 89 | J47: =IFERROR('Data Sheet'!I57,0) -> 89 | ... L47: =IFERROR('Data Sheet'!K57,0) -> 89
B48: Reserves | C48: =IFERROR('Data Sheet'!B58,0) -> 3417.5 | D48: =IFERROR('Data Sheet'!C58,0) -> 4143.6 | E48: =IFERROR('Data Sheet'!D58,0) -> 5001.1 | F48: =IFERROR('Data Sheet'!E58,0) -> 5981.37 | G48: =IFERROR('Data Sheet'!F58,0) -> 6580 | H48: =IFERROR('Data Sheet'!G58,0) -> 7408 | I48: =IFERROR('Data Sheet'!H58,0) -> 9214 | J48: =IFERROR('Data Sheet'!I58,0) -> 11762 | ... L48: =IFERROR('Data Sheet'!K58,0) -> 11535
B49: Borrowings | C49: =IFERROR('Data Sheet'!B59,0) -> 113.05 | D49: =IFERROR('Data Sheet'!C59,0) -> 1882.43 | E49: =IFERROR('Data Sheet'!D59,0) -> 1691.01 | F49: =IFERROR('Data Sheet'!E59,0) -> 2392.98 | G49: =IFERROR('Data Sheet'!F59,0) -> 3562 | H49: =IFERROR('Data Sheet'!G59,0) -> 5638 | I49: =IFERROR('Data Sheet'!H59,0) -> 7275 | J49: =IFERROR('Data Sheet'!I59,0) -> 9367 | ... L49: =IFERROR('Data Sheet'!K59,0) -> 20777
B50: Other Liabilities | C50: =IFERROR('Data Sheet'!B60,0) -> 2722.58 | D50: =IFERROR('Data Sheet'!C60,0) -> 2292.76 | E50: =IFERROR('Data Sheet'!D60,0) -> 2740.15 | F50: =IFERROR('Data Sheet'!E60,0) -> 3246.71 | G50: =IFERROR('Data Sheet'!F60,0) -> 3313 | H50: =IFERROR('Data Sheet'!G60,0) -> 3309 | I50: =IFERROR('Data Sheet'!H60,0) -> 4610 | J50: =IFERROR('Data Sheet'!I60,0) -> 5802 | ... L50: =IFERROR('Data Sheet'!K60,0) -> 8244
B51: Total Liabilities | C51: =IFERROR('Data Sheet'!B61,0) -> 6341.91 | D51: =IFERROR('Data Sheet'!C61,0) -> 8407.57 | E51: =IFERROR('Data Sheet'!D61,0) -> 9521.04 | F51: =IFERROR('Data Sheet'!E61,0) -> 11709.84 | G51: =IFERROR('Data Sheet'!F61,0) -> 13544 | H51: =IFERROR('Data Sheet'!G61,0) -> 16444 | I51: =IFERROR('Data Sheet'!H61,0) -> 21188 | J51: =IFERROR('Data Sheet'!I61,0) -> 27020 | ... L51: =IFERROR('Data Sheet'!K61,0) -> 40645
B53: Fixed Assets Net Block | C53: =IFERROR('Data Sheet'!B62,0) -> 770.54 | D53: =IFERROR('Data Sheet'!C62,0) -> 1188.72 | E53: =IFERROR('Data Sheet'!D62,0) -> 1473.81 | F53: =IFERROR('Data Sheet'!E62,0) -> 1566.63 | G53: =IFERROR('Data Sheet'!F62,0) -> 2633 | H53: =IFERROR('Data Sheet'!G62,0) -> 2523 | I53: =IFERROR('Data Sheet'!H62,0) -> 2544 | J53: =IFERROR('Data Sheet'!I62,0) -> 2998 | ... L53: =IFERROR('Data Sheet'!K62,0) -> 4062
B54: Capital Work in Progress | C54: =IFERROR('Data Sheet'!B63,0) -> 106.71 | D54: =IFERROR('Data Sheet'!C63,0) -> 152.07 | E54: =IFERROR('Data Sheet'!D63,0) -> 43.37 | F54: =IFERROR('Data Sheet'!E63,0) -> 31.77 | G54: =IFERROR('Data Sheet'!F63,0) -> 18 | H54: =IFERROR('Data Sheet'!G63,0) -> 32 | I54: =IFERROR('Data Sheet'!H63,0) -> 85 | J54: =IFERROR('Data Sheet'!I63,0) -> 144 | ... L54: =IFERROR('Data Sheet'!K63,0) -> 105
B55: Investments | C55: =IFERROR('Data Sheet'!B64,0) -> 30.41 | D55: =IFERROR('Data Sheet'!C64,0) -> 430.73 | E55: =IFERROR('Data Sheet'!D64,0) -> 35.99 | F55: =IFERROR('Data Sheet'!E64,0) -> 108.42 | G55: =IFERROR('Data Sheet'!F64,0) -> 158 | H55: =IFERROR('Data Sheet'!G64,0) -> 2824 | I55: =IFERROR('Data Sheet'!H64,0) -> 294 | J55: =IFERROR('Data Sheet'!I64,0) -> 2515 | ... L55: =IFERROR('Data Sheet'!K64,0) -> 1988
B56: Other Assets | C56: =IFERROR('Data Sheet'!B65-SUM('Data Sheet'!B67:B69),0) -> 678.25 | D56: =IFERROR('Data Sheet'!C65-SUM('Data Sheet'!C67:C69),0) -> 723.78 | E56: =IFERROR('Data Sheet'!D65-SUM('Data Sheet'!D67:D69),0) -> 1129.43 | F56: =IFERROR('Data Sheet'!E65-SUM('Data Sheet'!E67:E69),0) -> 1477.27 | G56: =IFERROR('Data Sheet'!F65-SUM('Data Sheet'!F67:F69),0) -> 1939 | H56: =IFERROR('Data Sheet'!G65-SUM('Data Sheet'!G67:G69),0) -> 1731 | I56: =IFERROR('Data Sheet'!H65-SUM('Data Sheet'!H67:H69),0) -> 2518 | J56: =IFERROR('Data Sheet'!I65-SUM('Data Sheet'!I67:I69),0) -> 2762 | ... L56: =IFERROR('Data Sheet'!K65-SUM('Data Sheet'!K67:K69),0) -> 3654
B57: Total Non Current Assets | C57: =IFERROR(SUM(C53:C56),0) -> 1585.91 | D57: =IFERROR(SUM(D53:D56),0) -> 2495.3 | E57: =IFERROR(SUM(E53:E56),0) -> 2682.6 | F57: =IFERROR(SUM(F53:F56),0) -> 3184.09 | G57: =IFERROR(SUM(G53:G56),0) -> 4748 | H57: =IFERROR(SUM(H53:H56),0) -> 7110 | I57: =IFERROR(SUM(I53:I56),0) -> 5441 | J57: =IFERROR(SUM(J53:J56),0) -> 8419 | ... L57: =IFERROR(SUM(L53:L56),0) -> 9809
...

Sheet Ratio Analysis
B2: ="Ratio Analysis of - "&'Data Sheet'!B1 -> Ratio Analysis of - TITAN COMPANY LTD
B3: Years | C3: ='Data Sheet'!B16 -> 42460 | D3: ='Data Sheet'!C16 -> 42825 | E3: ='Data Sheet'!D16 -> 43190 | F3: ='Data Sheet'!E16 -> 43555 | G3: ='Data Sheet'!F16 -> 43921 | H3: ='Data Sheet'!G16 -> 44286 | I3: ='Data Sheet'!H16 -> 44651 | J3: ='Data Sheet'!I16 -> 45016 | ... L3: ='Data Sheet'!K16 -> 45747 | M3: Trend | N3: Mean | O3: Median
B5: SalesGrowth | D5: =IFERROR(HistoricalFS!D7,0) -> 0.176034 | E5: =IFERROR(HistoricalFS!E7,0) -> 0.21559284 | F5: =IFERROR(HistoricalFS!F7,0) -> 0.22697284 | G5: =IFERROR(HistoricalFS!G7,0) -> 0.064387022 | H5: =IFERROR(HistoricalFS!H7,0) -> 0.028120844 | I5: =IFERROR(HistoricalFS!I7,0) -> 0.3305766 | J5: =IFERROR(HistoricalFS!J7,0) -> 0.40890309 | K5: =IFERROR(HistoricalFS!K7,0) -> 0.25900185 | L5: =IFERROR(HistoricalFS!L7,0) -> 0.18346253 | N5: =IFERROR(AVERAGE(D5:L5),0) -> 0.21033907 | O5: =IFERROR(MEDIAN(C5:L5),0) -> 0.21559284
B6: EBITDA Growth | D6: =IFERROR(HistoricalFS!D18/HistoricalFS!C18-1,0) -> 0.23907466 | E6: =IFERROR(HistoricalFS!E18/HistoricalFS!D18-1,0) -> 0.41266432 | F6: =IFERROR(HistoricalFS!F18/HistoricalFS!E18-1,0) -> 0.21262012 | G6: =IFERROR(HistoricalFS!G18/HistoricalFS!F18-1,0) -> 0.23533572 | H6: =IFERROR(HistoricalFS!H18/HistoricalFS!G18-1,0) -> -0.29963459 | I6: =IFERROR(HistoricalFS!I18/HistoricalFS!H18-1,0) -> 0.93855072 | J6: =IFERROR(HistoricalFS!J18/HistoricalFS!I18-1,0) -> 0.45992823 | K6: =IFERROR(HistoricalFS!K18/HistoricalFS!J18-1,0) -> 0.083981975 | L6: =IFERROR(HistoricalFS!L18/HistoricalFS!K18-1,0) -> 0.075963719 | N6: =IFERROR(AVERAGE(D6:L6),0) -> 0.26205387 | O6: =IFERROR(MEDIAN(C6:L6),0) -> 0.23533572
B7: EBIT Growth | D7: =IFERROR(HistoricalFS!D27/HistoricalFS!C27-1,0) -> 0.2714765 | E7: =IFERROR(HistoricalFS!E27/HistoricalFS!D27-1,0) -> 0.43738369 | F7: =IFERROR(HistoricalFS!F27/HistoricalFS!E27-1,0) -> 0.2182142 | G7: =IFERROR(HistoricalFS!G27/HistoricalFS!F27-1,0) -> 0.095922762 | H7: =IFERROR(HistoricalFS!H27/HistoricalFS!G27-1,0) -> -0.41149307 | I7: =IFERROR(HistoricalFS!I27/HistoricalFS!H27-1,0) -> 1.3775065 | J7: =IFERROR(HistoricalFS!J27/HistoricalFS!I27-1,0) -> 0.51851852 | K7: =IFERROR(HistoricalFS!K27/HistoricalFS!J27-1,0) -> -0.012557353 | L7: =IFERROR(HistoricalFS!L27/HistoricalFS!K27-1,0) -> -0.010026901 | N7: =IFERROR(AVERAGE(D7:L7),0) -> 0.27610499 | O7: =IFERROR(MEDIAN(C7:L7),0) -> 0.2182142
B8: Net Profit Growth | D8: =IFERROR(HistoricalFS!D33/HistoricalFS!C33-1,0) -> 0.21816894 | E8: =IFERROR(HistoricalFS!E33/HistoricalFS!D33-1,0) -> 0.39520861 | F8: =IFERROR(HistoricalFS!F33/HistoricalFS!E33-1,0) -> 0.17266807 | G8: =IFERROR(HistoricalFS!G33/HistoricalFS!F33-1,0) -> 0.10728245 | H8: =IFERROR(HistoricalFS!H33/HistoricalFS!G33-1,0) -> -0.40746269 | I8: =IFERROR(HistoricalFS!I33/HistoricalFS!H33-1,0) -> 1.5453401 | J8: =IFERROR(HistoricalFS!J33/HistoricalFS!I33-1,0) -> 0.46857991 | K8: =IFERROR(HistoricalFS!K33/HistoricalFS!J33-1,0) -> -0.0020215633 | L8: =IFERROR(HistoricalFS!L33/HistoricalFS!K33-1,0) -> -0.037812289 | N8: =IFERROR(AVERAGE(D8:L8),0) -> 0.27332794 | O8: =IFERROR(MEDIAN(C8:L8),0) -> 0.17266807
